Workbook

Sheet Instruções
A1: COMO USAR ESTA PLANILHA Controle de Compras — Materiais, Equipamentos e Ferramentas | Estoque BRITO
A4: 1. O que tem em cada aba
A5: • Instruções — esta página, com o passo a passo de uso do arquivo. • Visão Geral — dashboard com indicadores, o painel de itens em manutenção e os gráficos. Atualiza sozinha, não precisa editar nada nela. • Materiais Diversos — cadastro de todos os equipamentos e materiais diversos (menos ferramentas), um item por linha. • Ferramentas — cadastro exclusivo das ferramentas (itens portáteis usados nas obras), no mesmo formato da aba de Materiais.
A12: 2. Como cadastrar um novo item
A13: 1) Abra a aba 'Materiais Diversos' (equipamentos/materiais em geral) ou 'Ferramentas', conforme o tipo do item. 2) Vá até a primeira linha em branco logo abaixo do cabeçalho azul e comece a preencher da esquerda para a direita. 3) Nas colunas Categoria, Nome da Obra, Obra Atual, Estoque BRITO? e Status, clique na célula e use a setinha da lista suspensa — não digite manualmente, para evitar erro de digitação. 4) Preencha sempre 'Data da Compra' e 'Valor do Equipamento (R$)': são esses dois campos que alimentam os totais e gráficos da aba Visão Geral. 5) Preencha 'Data de Saída para Obra' sempre que enviar o item do Estoque BRITO para uma obra — é essa data que aparece no painel de manutenção quando o item precisar ser consertado. 6) O Nº de Patrimônio deve ser único: use o prefixo EQP- na aba de Materiais e FER- na aba de Ferramentas, seguidos de um número sequencial (ex.: EQP-0001, FER-0001).
A21: 3. Entendendo 'Obra Atual', 'Data de Saída' e 'Estoque BRITO'
A22: • Nome da Obra = a obra para a qual o item foi originalmente comprado. • Obra Atual = onde o item está fisicamente HOJE — pode ser essa mesma obra, outra obra (se foi transferido) ou 'Estoque BRITO'. • Data de Saída para Obra = quando o item saiu do Estoque BRITO rumo à 'Obra Atual'. Deixe em branco enquanto o item estiver parado no depósito. • Estoque BRITO? = 'Sim' quando o item está no depósito central (não alocado em nenhuma obra no momento) e 'Não' quando está em uso em uma obra. • Sempre que um item for transferido entre obras ou devolvido ao depósito, atualize essas colunas — é isso que mantém o dashboard confiável.
A29: 4. Painel de manutenção (o que você vê ao abrir o arquivo)
A30: • Ao abrir a planilha, vá até a aba 'Visão Geral': logo no topo, abaixo dos indicadores, fica o painel 'Itens em Manutenção Agora'. • Ele lista automaticamente todo item com Status = 'Manutenção', separado por Materiais Diversos e Ferramentas, mostrando patrimônio, descrição, obra atual e a data em que o item saiu para a obra. • Para tirar um item desse painel, basta trocar o Status dele (na aba de origem) para 'Em uso', 'Em estoque' ou 'Baixado' — ele some da lista sozinho.
A35: 5. Como funciona o restante do dashboard
A36: • Os cartões no topo (valor total investido, itens cadastrados, itens em Estoque BRITO, itens em obras e itens em manutenção) e todos os gráficos são calculados por fórmula. • Assim que você lança um item novo em 'Materiais Diversos' ou 'Ferramentas', o dashboard inteiro atualiza sozinho — não é preciso copiar nada manualmente. • O gráfico 'Compras nos últimos 12 meses' sempre mostra os 12 meses mais recentes a partir da data de hoje, ajustando-se sozinho com o tempo. • As tabelas de apoio dos gráficos ficam mais abaixo na mesma aba — também não precisam ser editadas.
A42: 6. Boas práticas para manter a planilha organizada
A43: • Um item por linha — nunca agrupe equipamentos diferentes na mesma linha. • Nunca reutilize um número de patrimônio já existente, mesmo que o item tenha sido baixado. • Prefira sempre selecionar valores da lista suspensa a digitar texto livre nas colunas de Categoria, Obra, Estoque BRITO? e Status. • Ao dar baixa em um item (perda, quebra irreparável, venda), mantenha a linha na planilha e apenas mude o Status para 'Baixado' — isso preserva o histórico de compras. • Revise mensalmente as colunas 'Obra Atual' e 'Status' com os encarregados de cada obra para manter o controle de patrimônio fiel à realidade.

Sheet Visão Geral
A1: DASHBOARD — SETOR DE COMPRAS | ESTOQUE BRITO
A2: Visão geral automática dos Materiais Diversos e Ferramentas cadastrados nas abas ao lado
A4: VALOR TOTAL INVESTIDO | D4: ITENS CADASTRADOS | G4: ITENS EM ESTOQUE BRITO | J4: ITENS ALOCADOS EM OBRAS | M4: ITENS EM MANUTENÇÃO
A5: =SUM('Materiais Diversos'!$K:$K)+SUM(Ferramentas!#REF!) -> #REF! | D5: =COUNTA('Materiais Diversos'!$A$3:$A$195)+COUNTA(Ferramentas!$A$3:$A$106) -> 0 | G5: =COUNTIF('Materiais Diversos'!$J:$J,"Sim")+COUNTIF(Ferramentas!$K:$K,"Sim") -> 0 | J5: =COUNTIF('Materiais Diversos'!$J:$J,"Não")+COUNTIF(Ferramentas!$K:$K,"Não") -> 0 | M5: =COUNTIF('Materiais Diversos'!$N:$N,"Manutenção")+COUNTIF(Ferramentas!$M:$M,"Manutenção") -> 0
A7: 🔧 ITENS EM MANUTENÇÃO AGORA
A8: Materiais Diversos | F8: Ferramentas
A9: Nº Patrimônio | B9: Descrição | C9: Obra Atual | D9: Data de Saída | F9: Nº Patrimônio | G9: Descrição | H9: Obra Atual | I9: Data de Saída
A10: =IFERROR(INDEX('Materiais Diversos'!$A$3:$A$195,MATCH(ROW()-9,'Materiais Diversos'!$O$3:$O$195,0)),"") | B10: =IFERROR(INDEX('Materiais Diversos'!$B$3:$B$195,MATCH(ROW()-9,'Materiais Diversos'!$O$3:$O$195,0)),"") | C10: =IFERROR(INDEX('Materiais Diversos'!$H$3:$H$195,MATCH(ROW()-9,'Materiais Diversos'!$O$3:$O$195,0)),"") | D10: =IFERROR(INDEX('Materiais Diversos'!$I$3:$I$195,MATCH(ROW()-9,'Materiais Diversos'!$O$3:$O$195,0)),"") | F10: =IFERROR(INDEX(Ferramentas!$A$3:$A$106,MATCH(ROW()-9,Ferramentas!$N$3:$N$106,0)),"") | G10: =IFERROR(INDEX(Ferramentas!$B$3:$B$106,MATCH(ROW()-9,Ferramentas!$N$3:$N$106,0)),"") | H10: =IFERROR(INDEX(Ferramentas!$I$3:$I$106,MATCH(ROW()-9,Ferramentas!$N$3:$N$106,0)),"") | I10: =IFERROR(INDEX(Ferramentas!$J$3:$J$106,MATCH(ROW()-9,Ferramentas!$N$3:$N$106,0)),"")
A11: =IFERROR(INDEX('Materiais Diversos'!$A$3:$A$195,MATCH(ROW()-9,'Materiais Diversos'!$O$3:$O$195,0)),"") | B11: =IFERROR(INDEX('Materiais Diversos'!$B$3:$B$195,MATCH(ROW()-9,'Materiais Diversos'!$O$3:$O$195,0)),"") | C11: =IFERROR(INDEX('Materiais Diversos'!$H$3:$H$195,MATCH(ROW()-9,'Materiais Diversos'!$O$3:$O$195,0)),"") | D11: =IFERROR(INDEX('Materiais Diversos'!$I$3:$I$195,MATCH(ROW()-9,'Materiais Diversos'!$O$3:$O$195,0)),"") | F11: =IFERROR(INDEX(Ferramentas!$A$3:$A$106,MATCH(ROW()-9,Ferramentas!$N$3:$N$106,0)),"") | G11: =IFERROR(INDEX(Ferramentas!$B$3:$B$106,MATCH(ROW()-9,Ferramentas!$N$3:$N$106,0)),"") | H11: =IFERROR(INDEX(Ferramentas!$I$3:$I$106,MATCH(ROW()-9,Ferramentas!$N$3:$N$106,0)),"") | I11: =IFERROR(INDEX(Ferramentas!$J$3:$J$106,MATCH(ROW()-9,Ferramentas!$N$3:$N$106,0)),"")
A12: =IFERROR(INDEX('Materiais Diversos'!$A$3:$A$195,MATCH(ROW()-9,'Materiais Diversos'!$O$3:$O$195,0)),"") | B12: =IFERROR(INDEX('Materiais Diversos'!$B$3:$B$195,MATCH(ROW()-9,'Materiais Diversos'!$O$3:$O$195,0)),"") | C12: =IFERROR(INDEX('Materiais Diversos'!$H$3:$H$195,MATCH(ROW()-9,'Materiais Diversos'!$O$3:$O$195,0)),"") | D12: =IFERROR(INDEX('Materiais Diversos'!$I$3:$I$195,MATCH(ROW()-9,'Materiais Diversos'!$O$3:$O$195,0)),"") | F12: =IFERROR(INDEX(Ferramentas!$A$3:$A$106,MATCH(ROW()-9,Ferramentas!$N$3:$N$106,0)),"") | G12: =IFERROR(INDEX(Ferramentas!$B$3:$B$106,MATCH(ROW()-9,Ferramentas!$N$3:$N$106,0)),"") | H12: =IFERROR(INDEX(Ferramentas!$I$3:$I$106,MATCH(ROW()-9,Ferramentas!$N$3:$N$106,0)),"") | I12: =IFERROR(INDEX(Ferramentas!$J$3:$J$106,MATCH(ROW()-9,Ferramentas!$N$3:$N$106,0)),"")
A13: =IFERROR(INDEX('Materiais Diversos'!$A$3:$A$195,MATCH(ROW()-9,'Materiais Diversos'!$O$3:$O$195,0)),"") | B13: =IFERROR(INDEX('Materiais Diversos'!$B$3:$B$195,MATCH(ROW()-9,'Materiais Diversos'!$O$3:$O$195,0)),"") | C13: =IFERROR(INDEX('Materiais Diversos'!$H$3:$H$195,MATCH(ROW()-9,'Materiais Diversos'!$O$3:$O$195,0)),"") | D13: =IFERROR(INDEX('Materiais Diversos'!$I$3:$I$195,MATCH(ROW()-9,'Materiais Diversos'!$O$3:$O$195,0)),"") | F13: =IFERROR(INDEX(Ferramentas!$A$3:$A$106,MATCH(ROW()-9,Ferramentas!$N$3:$N$106,0)),"") | G13: =IFERROR(INDEX(Ferramentas!$B$3:$B$106,MATCH(ROW()-9,Ferramentas!$N$3:$N$106,0)),"") | H13: =IFERROR(INDEX(Ferramentas!$I$3:$I$106,MATCH(ROW()-9,Ferramentas!$N$3:$N$106,0)),"") | I13: =IFERROR(INDEX(Ferramentas!$J$3:$J$106,MATCH(ROW()-9,Ferramentas!$N$3:$N$106,0)),"")
A14: =IFERROR(INDEX('Materiais Diversos'!$A$3:$A$195,MATCH(ROW()-9,'Materiais Diversos'!$O$3:$O$195,0)),"") | B14: =IFERROR(INDEX('Materiais Diversos'!$B$3:$B$195,MATCH(ROW()-9,'Materiais Diversos'!$O$3:$O$195,0)),"") | C14: =IFERROR(INDEX('Materiais Diversos'!$H$3:$H$195,MATCH(ROW()-9,'Materiais Diversos'!$O$3:$O$195,0)),"") | D14: =IFERROR(INDEX('Materiais Diversos'!$I$3:$I$195,MATCH(ROW()-9,'Materiais Diversos'!$O$3:$O$195,0)),"") | F14: =IFERROR(INDEX(Ferramentas!$A$3:$A$106,MATCH(ROW()-9,Ferramentas!$N$3:$N$106,0)),"") | G14: =IFERROR(INDEX(Ferramentas!$B$3:$B$106,MATCH(ROW()-9,Ferramentas!$N$3:$N$106,0)),"") | H14: =IFERROR(INDEX(Ferramentas!$I$3:$I$106,MATCH(ROW()-9,Ferramentas!$N$3:$N$106,0)),"") | I14: =IFERROR(INDEX(Ferramentas!$J$3:$J$106,MATCH(ROW()-9,Ferramentas!$N$3:$N$106,0)),"")
A15: =IFERROR(INDEX('Materiais Diversos'!$A$3:$A$195,MATCH(ROW()-9,'Materiais Diversos'!$O$3:$O$195,0)),"") | B15: =IFERROR(INDEX('Materiais Diversos'!$B$3:$B$195,MATCH(ROW()-9,'Materiais Diversos'!$O$3:$O$195,0)),"") | C15: =IFERROR(INDEX('Materiais Diversos'!$H$3:$H$195,MATCH(ROW()-9,'Materiais Diversos'!$O$3:$O$195,0)),"") | D15: =IFERROR(INDEX('Materiais Diversos'!$I$3:$I$195,MATCH(ROW()-9,'Materiais Diversos'!$O$3:$O$195,0)),"") | F15: =IFERROR(INDEX(Ferramentas!$A$3:$A$106,MATCH(ROW()-9,Ferramentas!$N$3:$N$106,0)),"") | G15: =IFERROR(INDEX(Ferramentas!$B$3:$B$106,MATCH(ROW()-9,Ferramentas!$N$3:$N$106,0)),"") | H15: =IFERROR(INDEX(Ferramentas!$I$3:$I$106,MATCH(ROW()-9,Ferramentas!$N$3:$N$106,0)),"") | I15: =IFERROR(INDEX(Ferramentas!$J$3:$J$106,MATCH(ROW()-9,Ferramentas!$N$3:$N$106,0)),"")
A16: =IFERROR(INDEX('Materiais Diversos'!$A$3:$A$195,MATCH(ROW()-9,'Materiais Diversos'!$O$3:$O$195,0)),"") | B16: =IFERROR(INDEX('Materiais Diversos'!$B$3:$B$195,MATCH(ROW()-9,'Materiais Diversos'!$O$3:$O$195,0)),"") | C16: =IFERROR(INDEX('Materiais Diversos'!$H$3:$H$195,MATCH(ROW()-9,'Materiais Diversos'!$O$3:$O$195,0)),"") | D16: =IFERROR(INDEX('Materiais Diversos'!$I$3:$I$195,MATCH(ROW()-9,'Materiais Diversos'!$O$3:$O$195,0)),"") | F16: =IFERROR(INDEX(Ferramentas!$A$3:$A$106,MATCH(ROW()-9,Ferramentas!$N$3:$N$106,0)),"") | G16: =IFERROR(INDEX(Ferramentas!$B$3:$B$106,MATCH(ROW()-9,Ferramentas!$N$3:$N$106,0)),"") | H16: =IFERROR(INDEX(Ferramentas!$I$3:$I$106,MATCH(ROW()-9,Ferramentas!$N$3:$N$106,0)),"") | I16: =IFERROR(INDEX(Ferramentas!$J$3:$J$106,MATCH(ROW()-9,Ferramentas!$N$3:$N$106,0)),"")
A17: =IFERROR(INDEX('Materiais Diversos'!$A$3:$A$195,MATCH(ROW()-9,'Materiais Diversos'!$O$3:$O$195,0)),"") | B17: =IFERROR(INDEX('Materiais Diversos'!$B$3:$B$195,MATCH(ROW()-9,'Materiais Diversos'!$O$3:$O$195,0)),"") | C17: =IFERROR(INDEX('Materiais Diversos'!$H$3:$H$195,MATCH(ROW()-9,'Materiais Diversos'!$O$3:$O$195,0)),"") | D17: =IFERROR(INDEX('Materiais Diversos'!$I$3:$I$195,MATCH(ROW()-9,'Materiais Diversos'!$O$3:$O$195,0)),"") | F17: =IFERROR(INDEX(Ferramentas!$A$3:$A$106,MATCH(ROW()-9,Ferramentas!$N$3:$N$106,0)),"") | G17: =IFERROR(INDEX(Ferramentas!$B$3:$B$106,MATCH(ROW()-9,Ferramentas!$N$3:$N$106,0)),"") | H17: =IFERROR(INDEX(Ferramentas!$I$3:$I$106,MATCH(ROW()-9,Ferramentas!$N$3:$N$106,0)),"") | I17: =IFERROR(INDEX(Ferramentas!$J$3:$J$106,MATCH(ROW()-9,Ferramentas!$N$3:$N$106,0)),"")
A18: =IFERROR(INDEX('Materiais Diversos'!$A$3:$A$195,MATCH(ROW()-9,'Materiais Diversos'!$O$3:$O$195,0)),"") | B18: =IFERROR(INDEX('Materiais Diversos'!$B$3:$B$195,MATCH(ROW()-9,'Materiais Diversos'!$O$3:$O$195,0)),"") | C18: =IFERROR(INDEX('Materiais Diversos'!$H$3:$H$195,MATCH(ROW()-9,'Materiais Diversos'!$O$3:$O$195,0)),"") | D18: =IFERROR(INDEX('Materiais Diversos'!$I$3:$I$195,MATCH(ROW()-9,'Materiais Diversos'!$O$3:$O$195,0)),"") | F18: =IFERROR(INDEX(Ferramentas!$A$3:$A$106,MATCH(ROW()-9,Ferramentas!$N$3:$N$106,0)),"") | G18: =IFERROR(INDEX(Ferramentas!$B$3:$B$106,MATCH(ROW()-9,Ferramentas!$N$3:$N$106,0)),"") | H18: =IFERROR(INDEX(Ferramentas!$I$3:$I$106,MATCH(ROW()-9,Ferramentas!$N$3:$N$106,0)),"") | I18: =IFERROR(INDEX(Ferramentas!$J$3:$J$106,MATCH(ROW()-9,Ferramentas!$N$3:$N$106,0)),"")
A19: =IFERROR(INDEX('Materiais Diversos'!$A$3:$A$195,MATCH(ROW()-9,'Materiais Diversos'!$O$3:$O$195,0)),"") | B19: =IFERROR(INDEX('Materiais Diversos'!$B$3:$B$195,MATCH(ROW()-9,'Materiais Diversos'!$O$3:$O$195,0)),"") | C19: =IFERROR(INDEX('Materiais Diversos'!$H$3:$H$195,MATCH(ROW()-9,'Materiais Diversos'!$O$3:$O$195,0)),"") | D19: =IFERROR(INDEX('Materiais Diversos'!$I$3:$I$195,MATCH(ROW()-9,'Materiais Diversos'!$O$3:$O$195,0)),"") | F19: =IFERROR(INDEX(Ferramentas!$A$3:$A$106,MATCH(ROW()-9,Ferramentas!$N$3:$N$106,0)),"") | G19: =IFERROR(INDEX(Ferramentas!$B$3:$B$106,MATCH(ROW()-9,Ferramentas!$N$3:$N$106,0)),"") | H19: =IFERROR(INDEX(Ferramentas!$I$3:$I$106,MATCH(ROW()-9,Ferramentas!$N$3:$N$106,0)),"") | I19: =IFERROR(INDEX(Ferramentas!$J$3:$J$106,MATCH(ROW()-9,Ferramentas!$N$3:$N$106,0)),"")
A20: =IFERROR(INDEX('Materiais Diversos'!$A$3:$A$195,MATCH(ROW()-9,'Materiais Diversos'!$O$3:$O$195,0)),"") | B20: =IFERROR(INDEX('Materiais Diversos'!$B$3:$B$195,MATCH(ROW()-9,'Materiais Diversos'!$O$3:$O$195,0)),"") | C20: =IFERROR(INDEX('Materiais Diversos'!$H$3:$H$195,MATCH(ROW()-9,'Materiais Diversos'!$O$3:$O$195,0)),"") | D20: =IFERROR(INDEX('Materiais Diversos'!$I$3:$I$195,MATCH(ROW()-9,'Materiais Diversos'!$O$3:$O$195,0)),"") | F20: =IFERROR(INDEX(Ferramentas!$A$3:$A$106,MATCH(ROW()-9,Ferramentas!$N$3:$N$106,0)),"") | G20: =IFERROR(INDEX(Ferramentas!$B$3:$B$106,MATCH(ROW()-9,Ferramentas!$N$3:$N$106,0)),"") | H20: =IFERROR(INDEX(Ferramentas!$I$3:$I$106,MATCH(ROW()-9,Ferramentas!$N$3:$N$106,0)),"") | I20: =IFERROR(INDEX(Ferramentas!$J$3:$J$106,MATCH(ROW()-9,Ferramentas!$N$3:$N$106,0)),"")
A21: =IFERROR(INDEX('Materiais Diversos'!$A$3:$A$195,MATCH(ROW()-9,'Materiais Diversos'!$O$3:$O$195,0)),"") | B21: =IFERROR(INDEX('Materiais Diversos'!$B$3:$B$195,MATCH(ROW()-9,'Materiais Diversos'!$O$3:$O$195,0)),"") | C21: =IFERROR(INDEX('Materiais Diversos'!$H$3:$H$195,MATCH(ROW()-9,'Materiais Diversos'!$O$3:$O$195,0)),"") | D21: =IFERROR(INDEX('Materiais Diversos'!$I$3:$I$195,MATCH(ROW()-9,'Materiais Diversos'!$O$3:$O$195,0)),"") | F21: =IFERROR(INDEX(Ferramentas!$A$3:$A$106,MATCH(ROW()-9,Ferramentas!$N$3:$N$106,0)),"") | G21: =IFERROR(INDEX(Ferramentas!$B$3:$B$106,MATCH(ROW()-9,Ferramentas!$N$3:$N$106,0)),"") | H21: =IFERROR(INDEX(Ferramentas!$I$3:$I$106,MATCH(ROW()-9,Ferramentas!$N$3:$N$106,0)),"") | I21: =IFERROR(INDEX(Ferramentas!$J$3:$J$106,MATCH(ROW()-9,Ferramentas!$N$3:$N$106,0)),"")
... A24: =IFERROR(INDEX('Materiais Diversos'!$A$3:$A$195,MATCH(ROW()-9,'Materiais Diversos'!$O$3:$O$195,0)),"") | B24: =IFERROR(INDEX('Materiais Diversos'!$B$3:$B$195,MATCH(ROW()-9,'Materiais Diversos'!$O$3:$O$195,0)),"") | C24: =IFERROR(INDEX('Materiais Diversos'!$H$3:$H$195,MATCH(ROW()-9,'Materiais Diversos'!$O$3:$O$195,0)),"") | D24: =IFERROR(INDEX('Materiais Diversos'!$I$3:$I$195,MATCH(ROW()-9,'Materiais Diversos'!$O$3:$O$195,0)),"") | F24: =IFERROR(INDEX(Ferramentas!$A$3:$A$106,MATCH(ROW()-9,Ferramentas!$N$3:$N$106,0)),"") | G24: =IFERROR(INDEX(Ferramentas!$B$3:$B$106,MATCH(ROW()-9,Ferramentas!$N$3:$N$106,0)),"") | H24: =IFERROR(INDEX(Ferramentas!$I$3:$I$106,MATCH(ROW()-9,Ferramentas!$N$3:$N$106,0)),"") | I24: =IFERROR(INDEX(Ferramentas!$J$3:$J$106,MATCH(ROW()-9,Ferramentas!$N$3:$N$106,0)),"")
A25: Mostra até 15 itens por aba, na ordem de cadastro. Some da lista automaticamente quando o Status deixar de ser 'Manutenção'.
A28: Tabelas de apoio aos gráficos (calculadas por fórmula — não editar manualmente)
A30: Localização | B30: Valor Total (R$) | D30: Categoria (Materiais) | E30: Quantidade
A31: Dialogo Alvaro Ramos | B31: =SUMIFS('Materiais Diversos'!$K:$K,'Materiais Diversos'!$H:$H,A31)+SUMIFS(Ferramentas!#REF!,Ferramentas!$I:$I,A31) -> #REF! | D31: Elétrica | E31: =COUNTIF('Materiais Diversos'!$C:$C,D31) -> 0
A32: Obra P.Raposo | B32: =SUMIFS('Materiais Diversos'!$K:$K,'Materiais Diversos'!$H:$H,A32)+SUMIFS(Ferramentas!#REF!,Ferramentas!$I:$I,A32) -> #REF! | D32: Hidráulica | E32: =COUNTIF('Materiais Diversos'!$C:$C,D32) -> 0
A33: JVM Casa Alba | B33: =SUMIFS('Materiais Diversos'!$K:$K,'Materiais Diversos'!$H:$H,A33)+SUMIFS(Ferramentas!#REF!,Ferramentas!$I:$I,A33) -> #REF! | D33: Alvenaria/Estrutura | E33: =COUNTIF('Materiais Diversos'!$C:$C,D33) -> 0
B34: =SUMIFS('Materiais Diversos'!$K:$K,'Materiais Diversos'!$H:$H,A34)+SUMIFS(Ferramentas!#REF!,Ferramentas!$I:$I,A34) -> #REF! | D34: Segurança (EPI) | E34: =COUNTIF('Materiais Diversos'!$C:$C,D34) -> 0
B35: =SUMIFS('Materiais Diversos'!$K:$K,'Materiais Diversos'!$H:$H,A35)+SUMIFS(Ferramentas!#REF!,Ferramentas!$I:$I,A35) -> #REF! | D35: Movimentação de Carga | E35: =COUNTIF('Materiais Diversos'!$C:$C,D35) -> 0
B36: =SUMIFS('Materiais Diversos'!$K:$K,'Materiais Diversos'!$H:$H,A36)+SUMIFS(Ferramentas!#REF!,Ferramentas!$I:$I,A36) -> #REF! | D36: Pintura/Acabamento | E36: =COUNTIF('Materiais Diversos'!$C:$C,D36) -> 0
A39: Status | B39: Quantidade | D39: AnoMes | E39: Mês/Ano | F39: Valor de Compras (R$)
A40: Em uso | B40: =COUNTIF('Materiais Diversos'!$N:$N,A40)+COUNTIF(Ferramentas!$M:$M,A40) -> 0 | D40: =YEAR(EDATE(TODAY(),-11))*100+MONTH(EDATE(TODAY(),-11)) -> 202510 | E40: =CHOOSE(MONTH(EDATE(TODAY(),-11)),"jan","fev","mar","abr","mai","jun","jul","ago","set","out","nov","dez")&"/"&TEXT(MOD(YEAR(EDATE(TODAY(),-11)),100),"00") -> out/25 | F40: =SUMPRODUCT(('Materiais Diversos'!$F$3:$F$195<>"")*(YEAR('Materiais Diversos'!$F$3:$F$195)*100+MONTH('Materiais Diversos'!$F$3:$F$195)=D40)*'Materiais Diversos'!$K$3:$K$195)+SUMPRODUCT((Ferramentas!$D$3:$D$106<>"")*(YEAR(Ferramentas!$D$3:$D$106)*100+MONTH(Ferramentas!$D$3:$D$106)=D40)*Ferramentas!#REF!) -> #REF!
A41: Em estoque | B41: =COUNTIF('Materiais Diversos'!$N:$N,A41)+COUNTIF(Ferramentas!$M:$M,A41) -> 0 | D41: =YEAR(EDATE(TODAY(),-10))*100+MONTH(EDATE(TODAY(),-10)) -> 202511 | E41: =CHOOSE(MONTH(EDATE(TODAY(),-10)),"jan","fev","mar","abr","mai","jun","jul","ago","set","out","nov","dez")&"/"&TEXT(MOD(YEAR(EDATE(TODAY(),-10)),100),"00") -> nov/25 | F41: =SUMPRODUCT(('Materiais Diversos'!$F$3:$F$195<>"")*(YEAR('Materiais Diversos'!$F$3:$F$195)*100+MONTH('Materiais Diversos'!$F$3:$F$195)=D41)*'Materiais Diversos'!$K$3:$K$195)+SUMPRODUCT((Ferramentas!$D$3:$D$106<>"")*(YEAR(Ferramentas!$D$3:$D$106)*100+MONTH(Ferramentas!$D$3:$D$106)=D41)*Ferramentas!#REF!) -> #REF!
A42: Manutenção | B42: =COUNTIF('Materiais Diversos'!$N:$N,A42)+COUNTIF(Ferramentas!$M:$M,A42) -> 0 | D42: =YEAR(EDATE(TODAY(),-9))*100+MONTH(EDATE(TODAY(),-9)) -> 202512 | E42: =CHOOSE(MONTH(EDATE(TODAY(),-9)),"jan","fev","mar","abr","mai","jun","jul","ago","set","out","nov","dez")&"/"&TEXT(MOD(YEAR(EDATE(TODAY(),-9)),100),"00") -> dez/25 | F42: =SUMPRODUCT(('Materiais Diversos'!$F$3:$F$195<>"")*(YEAR('Materiais Diversos'!$F$3:$F$195)*100+MONTH('Materiais Diversos'!$F$3:$F$195)=D42)*'Materiais Diversos'!$K$3:$K$195)+SUMPRODUCT((Ferramentas!$D$3:$D$106<>"")*(YEAR(Ferramentas!$D$3:$D$106)*100+MONTH(Ferramentas!$D$3:$D$106)=D42)*Ferramentas!#REF!) -> #REF!
A43: Baixado | B43: =COUNTIF('Materiais Diversos'!$N:$N,A43)+COUNTIF(Ferramentas!$M:$M,A43) -> 0 | D43: =YEAR(EDATE(TODAY(),-8))*100+MONTH(EDATE(TODAY(),-8)) -> 202601 | E43: =CHOOSE(MONTH(EDATE(TODAY(),-8)),"jan","fev","mar","abr","mai","jun","jul","ago","set","out","nov","dez")&"/"&TEXT(MOD(YEAR(EDATE(TODAY(),-8)),100),"00") -> jan/26 | F43: =SUMPRODUCT(('Materiais Diversos'!$F$3:$F$195<>"")*(YEAR('Materiais Diversos'!$F$3:$F$195)*100+MONTH('Materiais Diversos'!$F$3:$F$195)=D43)*'Materiais Diversos'!$K$3:$K$195)+SUMPRODUCT((Ferramentas!$D$3:$D$106<>"")*(YEAR(Ferramentas!$D$3:$D$106)*100+MONTH(Ferramentas!$D$3:$D$106)=D43)*Ferramentas!#REF!) -> #REF!
D44: =YEAR(EDATE(TODAY(),-7))*100+MONTH(EDATE(TODAY(),-7)) -> 202602 | E44: =CHOOSE(MONTH(EDATE(TODAY(),-7)),"jan","fev","mar","abr","mai","jun","jul","ago","set","out","nov","dez")&"/"&TEXT(MOD(YEAR(EDATE(TODAY(),-7)),100),"00") -> fev/26 | F44: =SUMPRODUCT(('Materiais Diversos'!$F$3:$F$195<>"")*(YEAR('Materiais Diversos'!$F$3:$F$195)*100+MONTH('Materiais Diversos'!$F$3:$F$195)=D44)*'Materiais Diversos'!$K$3:$K$195)+SUMPRODUCT((Ferramentas!$D$3:$D$106<>"")*(YEAR(Ferramentas!$D$3:$D$106)*100+MONTH(Ferramentas!$D$3:$D$106)=D44)*Ferramentas!#REF!) -> #REF!
D45: =YEAR(EDATE(TODAY(),-6))*100+MONTH(EDATE(TODAY(),-6)) -> 202603 | E45: =CHOOSE(MONTH(EDATE(TODAY(),-6)),"jan","fev","mar","abr","mai","jun","jul","ago","set","out","nov","dez")&"/"&TEXT(MOD(YEAR(EDATE(TODAY(),-6)),100),"00") -> mar/26 | F45: =SUMPRODUCT(('Materiais Diversos'!$F$3:$F$195<>"")*(YEAR('Materiais Diversos'!$F$3:$F$195)*100+MONTH('Materiais Diversos'!$F$3:$F$195)=D45)*'Materiais Diversos'!$K$3:$K$195)+SUMPRODUCT((Ferramentas!$D$3:$D$106<>"")*(YEAR(Ferramentas!$D$3:$D$106)*100+MONTH(Ferramentas!$D$3:$D$106)=D45)*Ferramentas!#REF!) -> #REF!
D46: =YEAR(EDATE(TODAY(),-5))*100+MONTH(EDATE(TODAY(),-5)) -> 202604 | E46: =CHOOSE(MONTH(EDATE(TODAY(),-5)),"jan","fev","mar","abr","mai","jun","jul","ago","set","out","nov","dez")&"/"&TEXT(MOD(YEAR(EDATE(TODAY(),-5)),100),"00") -> abr/26 | F46: =SUMPRODUCT(('Materiais Diversos'!$F$3:$F$195<>"")*(YEAR('Materiais Diversos'!$F$3:$F$195)*100+MONTH('Materiais Diversos'!$F$3:$F$195)=D46)*'Materiais Diversos'!$K$3:$K$195)+SUMPRODUCT((Ferramentas!$D$3:$D$106<>"")*(YEAR(Ferramentas!$D$3:$D$106)*100+MONTH(Ferramentas!$D$3:$D$106)=D46)*Ferramentas!#REF!) -> #REF!
D47: =YEAR(EDATE(TODAY(),-4))*100+MONTH(EDATE(TODAY(),-4)) -> 202605 | E47: =CHOOSE(MONTH(EDATE(TODAY(),-4)),"jan","fev","mar","abr","mai","jun","jul","ago","set","out","nov","dez")&"/"&TEXT(MOD(YEAR(EDATE(TODAY(),-4)),100),"00") -> mai/26 | F47: =SUMPRODUCT(('Materiais Diversos'!$F$3:$F$195<>"")*(YEAR('Materiais Diversos'!$F$3:$F$195)*100+MONTH('Materiais Diversos'!$F$3:$F$195)=D47)*'Materiais Diversos'!$K$3:$K$195)+SUMPRODUCT((Ferramentas!$D$3:$D$106<>"")*(YEAR(Ferramentas!$D$3:$D$106)*100+MONTH(Ferramentas!$D$3:$D$106)=D47)*Ferramentas!#REF!) -> #REF!
D48: =YEAR(EDATE(TODAY(),-3))*100+MONTH(EDATE(TODAY(),-3)) -> 202606 | E48: =CHOOSE(MONTH(EDATE(TODAY(),-3)),"jan","fev","mar","abr","mai","jun","jul","ago","set","out","nov","dez")&"/"&TEXT(MOD(YEAR(EDATE(TODAY(),-3)),100),"00") -> jun/26 | F48: =SUMPRODUCT(('Materiais Diversos'!$F$3:$F$195<>"")*(YEAR('Materiais Diversos'!$F$3:$F$195)*100+MONTH('Materiais Diversos'!$F$3:$F$195)=D48)*'Materiais Diversos'!$K$3:$K$195)+SUMPRODUCT((Ferramentas!$D$3:$D$106<>"")*(YEAR(Ferramentas!$D$3:$D$106)*100+MONTH(Ferramentas!$D$3:$D$106)=D48)*Ferramentas!#REF!) -> #REF!
D49: =YEAR(EDATE(TODAY(),-2))*100+MONTH(EDATE(TODAY(),-2)) -> 202607 | E49: =CHOOSE(MONTH(EDATE(TODAY(),-2)),"jan","fev","mar","abr","mai","jun","jul","ago","set","out","nov","dez")&"/"&TEXT(MOD(YEAR(EDATE(TODAY(),-2)),100),"00") -> jul/26 | F49: =SUMPRODUCT(('Materiais Diversos'!$F$3:$F$195<>"")*(YEAR('Materiais Diversos'!$F$3:$F$195)*100+MONTH('Materiais Diversos'!$F$3:$F$195)=D49)*'Materiais Diversos'!$K$3:$K$195)+SUMPRODUCT((Ferramentas!$D$3:$D$106<>"")*(YEAR(Ferramentas!$D$3:$D$106)*100+MONTH(Ferramentas!$D$3:$D$106)=D49)*Ferramentas!#REF!) -> #REF!
...

Sheet Materiais Diversos
A1: MATERIAIS DIVERSOS / EQUIPAMENTOS — ESTOQUE BRITO
A2: Nº Patrimônio | B2: Descrição do Item | C2: Quntidade | D2: Saldo | E2: Nº do Pedido | F2: Data da Compra | G2: Nome da Obra (destino da compra) | H2: Obra Atual (localização) | I2: Data de Saída para Obra | J2: Estoque BRITO? | K2: Valor do Equipamento (R$) | L2: Nº da Nota Fiscal | M2: Fornecedor | N2: Status
B6: ARCO SERRA "12" | C6: 12 | O6: =IF($N6="Manutenção",COUNTIF($N$3:$N6,"Manutenção"),"")
B7: CADEADO DE 30mm | C7: 0 | O7: =IF($N7="Manutenção",COUNTIF($N$3:$N7,"Manutenção"),"")
B8: CADEADO DE 50mm | C8: 0 | O8: =IF($N8="Manutenção",COUNTIF($N$3:$N8,"Manutenção"),"")
B9: CARRINHO DE MÃO | C9: 2 | O9: =IF($N9="Manutenção",COUNTIF($N$3:$N9,"Manutenção"),"")
B10: CHAVE GRIFO | C10: 3 | O10: =IF($N10="Manutenção",COUNTIF($N$3:$N10,"Manutenção"),"")
B11: CHAVE TORK | C11: 1 | O11: =IF($N11="Manutenção",COUNTIF($N$3:$N11,"Manutenção"),"")
B12: COLHER PEDREIRO | C12: 3 | O12: =IF($N12="Manutenção",COUNTIF($N$3:$N12,"Manutenção"),"")
B13: DESEMPENADEIRA | C13: 6 | O13: =IF($N13="Manutenção",COUNTIF($N$3:$N13,"Manutenção"),"")
B14: DISCO DE CORTE AÇO 4.1/2 | C14: 49 | O14: =IF($N14="Manutenção",COUNTIF($N$3:$N14,"Manutenção"),"")
B15: DISCO MAQUITA | C15: 7 | O15: =IF($N15="Manutenção",COUNTIF($N$3:$N15,"Manutenção"),"")
B16: ESCADAS FIBRA | C16: 6 | O16: =IF($N16="Manutenção",COUNTIF($N$3:$N16,"Manutenção"),"")
B17: ESCADAS DE MADEIRA ABRE/FECHA | C17: 11 | O17: =IF($N17="Manutenção",COUNTIF($N$3:$N17,"Manutenção"),"")
... B50: SUPORTE VERTICAL LASER | C50: 1 | O50: =IF($N50="Manutenção",COUNTIF($N$3:$N50,"Manutenção"),"")
O51: =IF($N51="Manutenção",COUNTIF($N$3:$N51,"Manutenção"),"")
O52: =IF($N52="Manutenção",COUNTIF($N$3:$N52,"Manutenção"),"")
B53: ESCRITÓRIO MATERIAL USO DIARIO
O54: =IF($N54="Manutenção",COUNTIF($N$3:$N54,"Manutenção"),"")
B55: BROCA CHATA 1.1/4 | O55: =IF($N55="Manutenção",COUNTIF($N$3:$N55,"Manutenção"),"")
B56: BROCA NORNAL 20" CONCRETO | O56: =IF($N56="Manutenção",COUNTIF($N$3:$N56,"Manutenção"),"")
B57: BROCA SDS PLUS "10" | O57: =IF($N57="Manutenção",COUNTIF($N$3:$N57,"Manutenção"),"")
B58: BROCA SDS PLUS "12" | O58: =IF($N58="Manutenção",COUNTIF($N$3:$N58,"Manutenção"),"")
B59: BROCA SDS PLUS "14" | O59: =IF($N59="Manutenção",COUNTIF($N$3:$N59,"Manutenção"),"")
B60: BROCA SDS PLUS "20" | O60: =IF($N60="Manutenção",COUNTIF($N$3:$N60,"Manutenção"),"")
B61: BROCA SDS PLUS "5" | O61: =IF($N61="Manutenção",COUNTIF($N$3:$N61,"Manutenção"),"")
B62: BROCA SDS PLUS "6" | O62: =IF($N62="Manutenção",COUNTIF($N$3:$N62,"Manutenção"),"")
B63: BROCA SDS PLUS "8" | O63: =IF($N63="Manutenção",COUNTIF($N$3:$N63,"Manutenção"),"")
B64: BROCA AÇO RAPIDO DE 1/4 | O64: =IF($N64="Manutenção",COUNTIF($N$3:$N64,"Manutenção"),"")
B65: BROCA AÇO RAPIDO DE 3/8 | O65: =IF($N65="Manutenção",COUNTIF($N$3:$N65,"Manutenção"),"")
B66: CADEADO DE 30mm | O66: =IF($N66="Manutenção",COUNTIF($N$3:$N66,"Manutenção"),"")
... B95: SERRA COPO BLOCO 4/2 | O95: =IF($N95="Manutenção",COUNTIF($N$3:$N95,"Manutenção"),"")
O96: =IF($N96="Manutenção",COUNTIF($N$3:$N96,"Manutenção"),"")
O97: =IF($N97="Manutenção",COUNTIF($N$3:$N97,"Manutenção"),"")
O98: =IF($N98="Manutenção",COUNTIF($N$3:$N98,"Manutenção"),"")
O99: =IF($N99="Manutenção",COUNTIF($N$3:$N99,"Manutenção"),"")
O100: =IF($N100="Manutenção",COUNTIF($N$3:$N100,"Manutenção"),"")
O101: =IF($N101="Manutenção",COUNTIF($N$3:$N101,"Manutenção"),"")
O102: =IF($N102="Manutenção",COUNTIF($N$3:$N102,"Manutenção"),"")
O103: =IF($N103="Manutenção",COUNTIF($N$3:$N103,"Manutenção"),"")
...

Sheet Ferramentas
A1: FERRAMENTAS — ESTOQUE BRITO
A2: Nº Patrimônio | B2: Descrição do Item | C2: Nº do Pedido | D2: Data da Compra | E2: Nº da Nota Fiscal | F2: Valor do Equipamento (R$) | G2: QUANTIDADE COMPRAD | H2: Fornecedor | I2: Obra Atual (localização) | J2: Data de Saída para Obra | K2: Estoque | L2: SAIDA | M2: Obra Atual (localização)
B3: ALIC ALARG TUBO DE COBRE 3/8, ½, 5/8, ¾, 7/8, 1.1/8 | K3: 1 | N3: =IF($M3="Manutenção",COUNTIF($M$3:$M3,"Manutenção"),"")
B4: ALIC PEX AGUA/GAS 16-20-25-32MM (gás) | D4: 45793 | E4: 564538 | F4: 1490 | H4: PIZZIMENTI | K4: 1 | N4: =IF($M4="Manutenção",COUNTIF($M$3:$M4,"Manutenção"),"")
B5: ALIC PRENSA TUBOS 16/20/26/32MM (prensa pex) | G5: 1 | I5: BRITO | K5: 1 | N5: =IF($M5="Manutenção",COUNTIF($M$3:$M5,"Manutenção"),"")
B6: CHAVE GRIFO | N6: =IF($M6="Manutenção",COUNTIF($M$3:$M6,"Manutenção"),"")
B7: CHAVE TORK | N7: =IF($M7="Manutenção",COUNTIF($M$3:$M7,"Manutenção"),"")
B8: ESMERILHADEIRA ANGULAR 710W BOSCH | D8: 45464 | E8: 529028 | F8: 334 | G8: 1 | H8: PIZZIMENTI | I8: ÁLVARO RAMOS | L8: 1 | M8: ÁLVARO RAMOS
B9: ESMERILHADEIRA ANGULAR 710W BOSCH | G9: 1 | H9: PIZZIMENTI | J9: 46269 | L9: 1 | M9: MANUTENÇÃO OÇA
B10: ESMERILHADEIRA ANGULAR 710W BOSCH | C10: 263/2026 | D10: 46268 | E10: 611844 | G10: 1 | H10: PIZZIMENTI
B12: EXTENÇÃO 20 METROS CABO PP | G12: 1 | I12: ÁLVARO RAMOS | K12: 1 | L12: 1 | M12: ÁLVARO RAMOS
B13: FORMÃO 1.1/4
B14: FURADEIRA IMPA SDS BOSH | D14: 45464 | E14: 529028 | F14: 783 | G14: 1 | H14: PIZZIMENTI | I14: ÁLVARO RAMOS | L14: 1 | M14: ÁLVARO RAMOS | N14: =IF($M14="Manutenção",COUNTIF($M$3:$M14,"Manutenção"),"")
B15: FURADEIRA IMPA SDS BOSH | G15: 1 | H15: PIZZIMENTI | I15: ÁLVARO RAMOS | L15: 1
B16: FURADEIRA IMPA SDS BOSH | G16: 1 | H16: PIZZIMENTI | J16: 46269 | M16: MANUTENÇÃO OÇA
B17: FURADEIRA IMPA SDS BOSH | C17: 263/2026 | D17: 46268 | E17: 611844 | F17: 840.36 | G17: 3 | H17: PIZZIMENTI | I17: ESC.DIALAGO | J17: 46274 | K17: =G17-L17 -> 2 | L17: 1 | M17: ESC.DIALAGO
B19: FURADEIRA DE MANDRIL HP 1640 MAKITA | D19: 45770 | E19: 561917 | F19: 472.85 | G19: 1 | H19: PIZZIMENTI | I19: PADRE RAPOSO | J19: 46289 | L19: 1 | M19: PADRE RAPOSO
B20: FURADEIRA DE MANDRIL HP 1640 MAKITA | D20: 45770 | E20: 561917 | F20: 472.85 | G20: 1 | H20: PIZZIMENTI | I20: BRITO USADA | K20: 1
B21: FURADEIRA DE MANDRIL HP 1640 MAKITA | G21: 1 | I21: BRITO NOVA | K21: 1
B22: FURADEIRA DE MANDRIL HP 1640 MAKITA | G22: 1 | I22: BRITO NOVA | K22: 1
B23: FURADEIRA DE MANDRIL HP 1640 MAKITA | G23: 1 | J23: 46269 | M23: MANUTENÇÃO OÇA | N23: =IF($M23="Manutenção",COUNTIF($M$3:$M23,"Manutenção"),"")
B25: LASER BOSCH | N25: =IF($M25="Manutenção",COUNTIF($M$3:$M25,"Manutenção"),"")
B26: LASER TRESNNA | G26: 1 | I26: BRITO | N26: =IF($M26="Manutenção",COUNTIF($M$3:$M26,"Manutenção"),"")
B27: LIXADEIRA OSCILANTE (VONDER) | G27: 1 | I27: ALVARO RAMOS | N27: =IF($M27="Manutenção",COUNTIF($M$3:$M27,"Manutenção"),"")
B28: MANDRIL BOSCH SDS | N28: =IF($M28="Manutenção",COUNTIF($M$3:$M28,"Manutenção"),"")
B29: MAQUINA SERRA CORTE MSC 2600 BANCADA POLICORTE | G29: 1 | I29: BRITO | N29: =IF($M29="Manutenção",COUNTIF($M$3:$M29,"Manutenção"),"")
B30: SERRA DE CORTE 4100 NH3 MAKITA | G30: 1 | I30: BRITO | N30: =IF($M30="Manutenção",COUNTIF($M$3:$M30,"Manutenção"),"")
B31: MARTELETE | N31: =IF($M31="Manutenção",COUNTIF($M$3:$M31,"Manutenção"),"")
B32: MASSARICO | N32: =IF($M32="Manutenção",COUNTIF($M$3:$M32,"Manutenção"),"")
B33: MEGOMETRO | N33: =IF($M33="Manutenção",COUNTIF($M$3:$M33,"Manutenção"),"")
B34: MORSA PARA BANCADA 4 pol | N34: =IF($M34="Manutenção",COUNTIF($M$3:$M34,"Manutenção"),"")
B35: NIVEL ALMA 30cm | N35: =IF($M35="Manutenção",COUNTIF($M$3:$M35,"Manutenção"),"")
B36: PARAFUSADEIRA/CHAVE IMPAC WAP | N36: =IF($M36="Manutenção",COUNTIF($M$3:$M36,"Manutenção"),"")
B37: PARAFUSADEIRA A BATERIA BOSCH | D37: 45464 | E37: 529028 | F37: 799 | G37: 1 | I37: BRITO | N37: =IF($M37="Manutenção",COUNTIF($M$3:$M37,"Manutenção"),"")
B38: PARAFUSADEIRA BOSCH | N38: =IF($M38="Manutenção",COUNTIF($M$3:$M38,"Manutenção"),"")
B39: PERFURATRIZ PLASTICON VERMELHA | F39: 2900 | G39: 1 | H39: PLASTICON | I39: BRITO
B40: PERFURATRIZ PLASTICON AZUL | F40: 2900 | G40: 2 | H40: PLASTICON | I40: BRITO | N40: =IF($M40="Manutenção",COUNTIF($M$3:$M40,"Manutenção"),"")
B41: PERFURATRIZ PLASTICON | F41: 2900 | G41: 1 | I41: ÁLVARO RAMOS
B42: PRENSA TERMINAL CABO | G42: 1 | I42: PADRE RAPOSO | N42: =IF($M42="Manutenção",COUNTIF($M$3:$M42,"Manutenção"),"")
B43: SERRA MARMORE (MAQUITA) | N43: =IF($M43="Manutenção",COUNTIF($M$3:$M43,"Manutenção"),"")
...
